Workbook

Sheet Resumen
A1: MER v2 · Facturación de agua CAAPD Ispacas
A2: Versión simplificada para Firebase gratuito: 8 entidades, una tabla nueva por mes y respaldo en Excel.
A4: Cifras del modelo
A5: Entidades | B5: =COUNTA(Entidades!A5:A12) -> 8
A6: Atributos | B6: =COUNTA(Atributos!B5:B51) -> 47
A7: Llaves primarias (incluye compuestas) | B7: =COUNTIF(Atributos!D5:D51,"*PK*") -> 11
A8: Llaves foráneas | B8: =COUNTIF(Atributos!D5:D51,"*FK*") -> 7
A9: Relaciones | B9: =COUNTA(Relaciones!A5:A11) -> 7
A11: Hojas
A12: Entidades | C12: Las 8 entidades y dónde vive cada una en Firestore.
A13: Atributos | C13: Diccionario de datos con formatos de ID, DNI y medidor.
A14: Relaciones | C14: Cardinalidades y llaves foráneas.
A15: Parametros | C15: Tarifas, colores de mora y constantes iniciales.
A16: Calculo_ejemplo | C16: Recibo calculado con fórmulas, comprobado contra 17.50, y ejemplos de ceros y guion.
A17: Firestore | C17: Estructura de la base en Firebase y consultas de cada parte.
A18: Mes_ejemplo | C18: Tabla del mes y formato del Excel de respaldo.
A19: Uso_gratuito | C19: Cuánto consume del plan gratuito, con fórmulas.
A20: Reglas_negocio | C20: Reglas, supuestos y pendientes.
A21: Migracion_datos | C21: Qué ordenar al importar tus dos Excel.
A23: Qué cambió respecto a la versión anterior
A24: 16 → 8 entidades | C24: Se quitaron sector, operador, concepto, detalle_recibo, nivel_mora, pago y pago_recibo: el recibo tiene 4 líneas fijas, el pago es una marca en el recibo y los colores de mora son parámetros.
A25: Usuario y conexión unidos | C25: Una persona = un código de conexión, aunque tenga varios medidores.
A26: Medidor | C26: Sin fechas de instalación ni retiro. Su número es su ID, con mínimo 6 dígitos.
A27: id_usuario = DNI | C27: 8 dígitos con ceros; -1 y -2 si lo comparten personas distintas; SD-001 si no hay. Con guion = pendiente.
A28: Tabla nueva cada mes | C28: Colección mes_aaaa-mm con lectura anterior y actual, recibo y pago, más Excel de respaldo.
A30: Leyenda de colores
A31: Texto azul | C31: Dato editable o de entrada.
A32: Texto verde | C32: Enlace a otra hoja.
A33: Texto negro | C33: Fórmula o texto fijo.
A34: Fondo amarillo | C34: Por definir o confirmar.

Sheet Entidades
A1: Entidades del MER (versión simplificada)
A2: 8 entidades. Cada mes se crea una tabla nueva con lecturas, recibos y pagos, igual al Excel.
A4: Entidad | B4: Tipo | C4: Propósito | D4: Dónde vive en Firestore | E4: Nº atributos
A5: usuario | B5: Maestra | C5: Persona (o institución) con servicio de agua. Una persona = un código de conexión, aunque tenga varios medidores. | D5: usuarios/{id_usuario} | E5: =COUNTIF(Atributos!$A$5:$A$200,A5) -> 7
A6: medidor | B6: Maestra | C6: Medidor de un usuario. Su número es también su ID (mínimo 6 dígitos). | D6: usuarios/{id}.medidores (lista) | E6: =COUNTIF(Atributos!$A$5:$A$200,A6) -> 3
A7: categoria | B7: Catálogo | C7: Categoría de tarifa A, B o C con desagüe y cargo fijo. | D7: config/general.categorias | E7: =COUNTIF(Atributos!$A$5:$A$200,A7) -> 4
A8: rango_tarifa | B8: Catálogo | C8: Rangos de m³ con su precio por m³, por categoría. | D8: config/general.categorias.*.rangos | E8: =COUNTIF(Atributos!$A$5:$A$200,A8) -> 4
A9: periodo | B9: Transaccional | C9: Mes de facturación. Cada mes crea una tabla nueva (colección). | D9: config/general.mes_actual + colección mes_aaaa-mm | E9: =COUNTIF(Atributos!$A$5:$A$200,A9) -> 4
A10: lectura | B10: Transaccional | C10: Lectura anterior y actual de un medidor en el mes. Es la parte del Excel de lecturas. | D10: mes_aaaa-mm/{id}.medidores (lista) | E10: =COUNTIF(Atributos!$A$5:$A$200,A10) -> 8
A11: recibo | B11: Transaccional | C11: Recibo del usuario en el mes: montos, deuda acumulada, meses adeudados y pago. | D11: mes_aaaa-mm/{id} (campos de recibo y pago) | E11: =COUNTIF(Atributos!$A$5:$A$200,A11) -> 14
A12: parametro | B12: Configuración | C12: Constantes editables: resolución, WhatsApp del QR, IGV, días de vencimiento, colores de mora. | D12: config/general | E12: =COUNTIF(Atributos!$A$5:$A$200,A12) -> 3

Sheet Atributos
A1: Diccionario de datos
A2: Clave: PK llave primaria, FK llave foránea, UK único. Obligatorio = No significa que acepta NULL.
A4: Entidad | B4: Atributo | C4: Tipo de dato | D4: Clave | E4: Referencia (FK →) | F4: Obligatorio | G4: Formato / descripción
A5: usuario | B5: id_usuario | C5: string | D5: PK | F5: Sí | G5: DNI de 8 dígitos con ceros adelante (7654321 → 07654321). Si el DNI lo comparten personas distintas: 07654321-1 y 07654321-2. Sin DNI: SD-001. Con guion = pendiente de corregir.
A6: usuario | B6: nro_conexion | C6: string | D6: UK | F6: Sí | G6: 6 dígitos (000796). Un solo código por persona.
A7: usuario | B7: nombre | C7: string | F7: Sí | G7: APELLIDO1 APELLIDO2, NOMBRES.
A8: usuario | B8: sector | C8: string | F8: Sí | G8: BARRIO DE LUCMANI, BARRIO DE CHAUPI, BARRIO DE PACHAYZA, HUAQUILLO, CHAUPICERCA o AYACUCHO.
A9: usuario | B9: direccion | C9: string | F9: Sí | G9: Texto libre.
A10: usuario | B10: codigo_categoria | C10: string | D10: FK | E10: categoria.codigo | F10: Sí | G10: A, B o C.
A11: usuario | B11: activo | C11: bool | F11: Sí | G11: Los inactivos no se importan.
A12: medidor | B12: nro_medidor | C12: string | D12: PK | F12: Sí | G12: Mínimo 6 dígitos con ceros adelante (100 → 000100). Si ya tiene 6 o más, no se cambia. Es también su ID.
A13: medidor | B13: id_usuario | C13: string | D13: FK | E13: usuario.id_usuario | F13: Sí | G13: Dueño del medidor. Un usuario puede tener varios.
A14: medidor | B14: activo | C14: bool | F14: Sí | G14: Un medidor reemplazado pasa a falso.
A15: categoria | B15: codigo | C15: string | D15: PK | F15: Sí | G15: A, B o C.
A16: categoria | B16: nombre | C16: string | F16: Sí | G16: Doméstico, Negocio pequeño, Hotel o Restaurante.
A17: categoria | B17: tarifa_desague | C17: decimal | F17: Sí | G17: Valor constante por categoría.
A18: categoria | B18: cargo_fijo | C18: decimal | F18: Sí | G18: Editable por el dueño.
A19: rango_tarifa | B19: codigo_categoria | C19: string | D19: PK, FK | E19: categoria.codigo | F19: Sí | G19: Categoría a la que aplica.
A20: rango_tarifa | B20: m3_desde | C20: decimal | D20: PK | F20: Sí | G20: Inicio del rango en m³.
A21: rango_tarifa | B21: m3_hasta | C21: decimal | F21: No | G21: NULL = sin tope.
A22: rango_tarifa | B22: precio_m3 | C22: decimal | F22: Sí | G22: Precio por m³ en el rango.
A23: periodo | B23: periodo | C23: string | D23: PK | F23: Sí | G23: aaaa-mm, ej. 2026-09. La temporada (AGOSTO 2026) se deriva de este dato.
A24: periodo | B24: fecha_emision | C24: date | F24: Sí | G24: Fecha de emisión de los recibos del mes.
A25: periodo | B25: fecha_vencimiento | C25: date | F25: Sí | G25: Último día de pago.
A26: periodo | B26: estado | C26: string | F26: Sí | G26: ABIERTO o FACTURADO.
A27: lectura | B27: periodo | C27: string | D27: PK, FK | E27: periodo.periodo | F27: Sí | G27: Mes de la lectura.
A28: lectura | B28: nro_medidor | C28: string | D28: PK, FK | E28: medidor.nro_medidor | F28: Sí | G28: Medidor leído.
A29: lectura | B29: lectura_anterior | C29: decimal | F29: Sí | G29: Copia de la lectura actual del mes previo. En un medidor nuevo, su lectura inicial.
A30: lectura | B30: fecha_anterior | C30: date | F30: No | G30: Copia de fecha_lectura del mes previo. Se imprime en el recibo como inicio del ciclo.
A31: lectura | B31: lectura_actual | C31: decimal | F31: No | G31: NULL hasta que el lector la ingrese.
A32: lectura | B32: fecha_lectura | C32: date | F32: No | G32: Se registra al guardar la lectura.
A33: lectura | B33: consumo_m3 | C33: decimal | F33: No | G33: lectura_actual − lectura_anterior. Editable si hay novedad.
A34: lectura | B34: novedad | C34: string | F34: No | G34: Ej. CAMBIO DE MEDIDOR. Obligatoria si la actual es menor que la anterior.
A35: recibo | B35: periodo | C35: string | D35: PK, FK | E35: periodo.periodo | F35: Sí | G35: Mes del recibo.
A36: recibo | B36: id_usuario | C36: string | D36: PK, FK | E36: usuario.id_usuario | F36: Sí | G36: Usuario facturado.
A37: recibo | B37: nro_recibo | C37: string | D37: UK | F37: Sí | G37: 9 dígitos (000058391), correlativo.
A38: recibo | B38: consumo_total_m3 | C38: decimal | F38: Sí | G38: Suma de los consumos de sus medidores.
A39: recibo | B39: monto_agua | C39: decimal | F39: Sí | G39: consumo × precio del rango (concepto 001).
A40: recibo | B40: monto_desague | C40: decimal | F40: Sí | G40: Constante por categoría (concepto 008).
A41: recibo | B41: cargo_fijo | C41: decimal | F41: Sí | G41: Editable por el dueño (concepto 407).
...

Sheet Relaciones
A1: Relaciones y cardinalidades
A2: Lado izquierdo : lado derecho. La llave foránea está en la entidad del lado N.
A4: Entidad A | B4: Entidad B | C4: Cardinalidad | D4: Verbo | E4: Llave foránea | F4: Nota
A5: categoria | B5: usuario | C5: 1 : N | D5: clasifica | E5: usuario.codigo_categoria | F5: Define la tarifa.
A6: categoria | B6: rango_tarifa | C6: 1 : N | D6: define | E6: rango_tarifa.codigo_categoria | F6: Rangos de precio por m³.
A7: usuario | B7: medidor | C7: 1 : 0..N | D7: posee | E7: medidor.id_usuario | F7: Una persona puede tener varios medidores y un solo código de conexión.
A8: periodo | B8: lectura | C8: 1 : N | D8: contiene | E8: lectura.periodo | F8: La tabla de lecturas del mes.
A9: medidor | B9: lectura | C9: 1 : N | D9: registra | E9: lectura.nro_medidor | F9: Una lectura por medidor y mes.
A10: periodo | B10: recibo | C10: 1 : N | D10: emite | E10: recibo.periodo | F10: Un recibo por usuario y mes.
A11: usuario | B11: recibo | C11: 1 : N | D11: recibe | E11: recibo.id_usuario | F11: El consumo del recibo es la suma de las lecturas de sus medidores.

Sheet Parametros
A1: Parámetros y catálogos iniciales
A2: Azul = editable · Amarillo = por definir o confirmar con el dueño. Todo esto vive en un solo documento: config/general.
A4: categoria
A5: codigo | B5: nombre | C5: tarifa_desague | D5: cargo_fijo | F5: Nota
A6: A | B6: Doméstico | C6: 0 | D6: 1.5 | F6: Desagüe 0.00 y cargo fijo 1.50 tomados del recibo de agosto 2026.
A7: B | B7: Negocio pequeño | F7: Por definir.
A8: C | B8: Hotel o Restaurante | F8: Por definir.
A10: rango_tarifa
A11: codigo_categoria | B11: m3_desde | C11: m3_hasta | D11: precio_m3 | F11: Nota
A12: A | B12: 0 | D12: 1 | F12: Inferido: 16 m³ = S/ 16.00 en el recibo de ejemplo. Confirmar rangos y si el precio aplica a todo el consumo o por tramos.
A13: B | B13: 0 | F13: Por definir.
A14: C | B14: 0 | F14: Por definir.
A16: colores de mora (dentro de parametro)
A17: meses_min | B17: nombre | C17: color_hex | D17: incluir_en_corte | F17: Nota
A18: 1 | B18: AZUL | C18: 1E88E5 | D18: =FALSE() -> FALSE | F18: Debe el mes.
A19: 2 | B19: NARANJA | C19: FB8C00 | D19: =FALSE() -> FALSE | F19: Debe 2 meses.
A20: 3 | B20: ROJO | C20: E53935 | D20: =TRUE() -> TRUE | F20: Debe 3 meses o más: entra al reporte de corte. Si el recibo está pagado no lleva color. Los hex son sugeridos.
A22: parametro
A23: clave | B23: valor | F23: Descripción
A24: RESOLUCION | B24: 192-2017 | F24: Resolución impresa en el recibo.
A25: IGV_ACTIVO | B25: =FALSE() -> FALSE | F25: Interruptor del IGV. En el recibo de ejemplo el IGV es 0.00.
A26: IGV_PORCENTAJE | B26: 0.18 | F26: Tasa del IGV (documento de variables: 18%). Se aplica solo a lo afecto.
A27: DIAS_VENCIMIENTO | B27: 15 | F27: Inferido: emisión 08-08-2026, vence 23-08-2026. Confirmar.
A28: WHATSAPP | F28: Número al que apunta el QR de consultas. Por definir.
A29: TELEFONO_COMITE | B29: 986054179 | F29: Celular del encabezado del recibo.
A30: ULTIMO_RECIBO | F30: Último número de recibo emitido; la PC suma 1 por cada recibo. Por definir.
A31: NOMBRE_COMITE | B31: COMITÉ DE ADMINISTRACIÓN DE AGUA POTABLE Y DESAGÜE DE LA COMUNIDAD CAMPESINA DE ISPACAS | F31: Encabezado del recibo.
A32: DIRECCION_COMITE | B32: Calle 5 de Agosto s/n - Distrito de Yanaquihua - Provincia de Condesuyos - Región Arequipa | F32: Encabezado del recibo.
A34: sectores (lista dentro de parametro)
A35: BARRIO DE CHAUPI | F35: Un sector = una hoja en el Excel de respaldo.
A36: BARRIO DE PACHAYZA | F36: Un sector = una hoja en el Excel de respaldo.
A37: BARRIO DE LUCMANI | F37: Un sector = una hoja en el Excel de respaldo.
A38: HUAQUILLO | F38: Un sector = una hoja en el Excel de respaldo.
A39: CHAUPICERCA | F39: Un sector = una hoja en el Excel de respaldo.
A40: AYACUCHO | F40: Un sector = una hoja en el Excel de respaldo.

Sheet Calculo_ejemplo
A1: Cálculo de un recibo (ejemplo)
A2: Reproduce el recibo de agosto 2026. Azul = editable · Verde = enlace a Parametros · Negro = fórmula.
A4: Entradas
A5: medidor 1: lectura_anterior | B5: 42 | C5: Recibo: L. Anterior 42.00
A6: medidor 1: lectura_actual | B6: 58 | C6: Recibo: L. Actual 58.00
A7: medidor 2: lectura_anterior | B7: 0 | C7: Opcional: una persona puede tener más medidores.
A8: medidor 2: lectura_actual | B8: 0
A9: recibo anterior: total_a_pagar | B9: 0 | C9: 0 = no hay recibo anterior.
A10: recibo anterior: monto_pagado | B10: 0
A11: recibo anterior: meses_adeudados | B11: 0
A12: este recibo: monto_pagado | B12: 0 | C12: Poner el total para ver el estado AL DIA.
A14: Parámetros (desde Parametros)
A15: precio_m3 | B15: =Parametros!D12 -> 1 | C15: Categoría A.
A16: tarifa_desague | B16: =Parametros!C6 -> 0
A17: cargo_fijo | B17: =Parametros!D6 -> 1.5
A18: IGV_ACTIVO | B18: =Parametros!B25 -> FALSE | C18: Cambia a VERDADERO en Parametros para probar el IGV.
A19: IGV_PORCENTAJE | B19: =Parametros!B26 -> 0.18
A21: Cálculo del recibo
A22: consumo_total_m3 | B22: =(B6-B5)+(B8-B7) -> 16 | C22: Suma de los medidores.
A23: monto_agua | B23: =ROUND(B22*B15,2) -> 16 | C23: consumo × precio_m3 (un solo rango supuesto).
A24: monto_desague | B24: =B16 -> 0
A25: cargo_fijo | B25: =B17 -> 1.5
A26: deuda_anterior | B26: =MAX(0,B9-B10) -> 0 | C26: Lo que quedó sin pagar del recibo anterior (ya incluye sus deudas previas).
A27: subtotal_afecto | B27: =B23+B24+B25 -> 17.5 | C27: Agua, desagüe y cargo fijo.
A28: igv | B28: =IF(B18,ROUND(B19*B27,2),0) -> 0 | C28: Solo sobre lo afecto (supuesto).
A29: total_antes_de_redondeo | B29: =B27+B26+B28 -> 17.5
A30: redondeo | B30: =ROUND(ROUND(B29,2)-TRUNC(ROUND(B29,2),1),2) -> 0 | C30: Se restan las centésimas.
A31: total_a_pagar | B31: =ROUND(B29,2)-B30 -> 17.5 | C31: Total antes de redondeo − redondeo.
A32: total_mes (sin deuda) | B32: =B31-B26 -> 17.5 | C32: Se imprime como TOTAL MES.
A34: Mora
A35: meses_adeudados | B35: =IF(B10>=B9,1,B11+1) -> 1 | C35: 1 si el anterior está pagado o no existe; si no, el anterior + 1.
A36: estado del recibo | B36: =IF(B12>=B31,"AL DIA",INDEX(Parametros!B18:B20,MATCH(B35,Parametros!A18:A20,1))) -> AZUL | C36: Color del recibo según Parametros.
A37: incluir_en_corte | B37: =IF(B12>=B31,FALSE(),INDEX(Parametros!D18:D20,MATCH(B35,Parametros!A18:A20,1))) -> FALSE
A39: Verificación con el recibo de ejemplo
A40: TOTAL A PAGAR impreso | B40: 17.5 | C40: Dato de la foto del recibo.
A41: Resultado | B41: =IF(ROUND(B31,2)=B40,"OK","REVISAR") -> OK | C41: Solo válido con las entradas originales.
A43: Formato de códigos (ceros a la izquierda y guion)
A44: Medidor (mínimo 6 dígitos) | B44: 100 | C44: =IF(LEN(B44)<6,TEXT(B44,"000000"),TEXT(B44,"0")) -> 000100
A45: Medidor (mínimo 6 dígitos) | B45: 3200 | C45: =IF(LEN(B45)<6,TEXT(B45,"000000"),TEXT(B45,"0")) -> 003200
A46: Medidor (mínimo 6 dígitos) | B46: 990991 | C46: =IF(LEN(B46)<6,TEXT(B46,"000000"),TEXT(B46,"0")) -> 990991
...

Sheet Firestore
A1: Base de datos en Firebase (Firestore) lo más simple
A2: 3 lugares: config/general, usuarios y una colección nueva por mes. Los nombres de campo son los mismos del MER.
A4: Colección / documento | B4: Campo | C4: Tipo | D4: Lo escribe | E4: Ejemplo | F4: Nota
A5: config/general | B5: empresa | C5: map | D5: PC | E5: {nombre, resolucion:"192-2017", telefono, whatsapp, direccion} | F5: Constantes del recibo.
A6: config/general | B6: igv | C6: map | D6: PC | E6: {activo:false, porcentaje:0.18}
A7: config/general | B7: dias_vencimiento | C7: number | D7: PC | E7: 15
A8: config/general | B8: ultimo_recibo | C8: number | D8: PC | E8: 58391 | F8: Correlativo.
A9: config/general | B9: sectores | C9: array<string> | D9: PC | E9: ["BARRIO DE CHAUPI", ...]
A10: config/general | B10: categorias | C10: map | D10: PC | E10: {A:{nombre:"Doméstico", tarifa_desague:0, cargo_fijo:1.5, rangos:[{m3_desde:0, m3_hasta:null, precio_m3:1}]}} | F10: Categorías y rangos juntos.
A11: config/general | B11: mora | C11: array<map> | D11: PC | E11: [{meses_min:1, nombre:"AZUL", color:"#1E88E5"}, {2,NARANJA}, {3,ROJO,corte:true}]
A12: config/general | B12: mes_actual | C12: map | D12: PC | E12: {periodo:"2026-09", fecha_emision:"2026-09-08", fecha_vencimiento:"2026-09-23", estado:"ABIERTO"} | F12: La app lee este documento para saber qué colección usar.
A13: usuarios/{id_usuario} | B13: (ID del documento) | C13: string | D13: PC | E13: 07654321 · 07654321-1 · SD-001 | F13: Con guion = pendiente de corregir el DNI.
A14: usuarios/{id_usuario} | B14: nro_conexion | C14: string | D14: PC | E14: 000796
A15: usuarios/{id_usuario} | B15: nombre | C15: string | D15: PC | E15: ALVAREZ CHUQUIYANQUI, MARIBEL NAYELI
A16: usuarios/{id_usuario} | B16: sector | C16: string | D16: PC | E16: BARRIO DE LUCMANI
A17: usuarios/{id_usuario} | B17: direccion | C17: string | D17: PC | E17: AUCAYPATA S/N
A18: usuarios/{id_usuario} | B18: codigo_categoria | C18: string | D18: PC | E18: A
A19: usuarios/{id_usuario} | B19: activo | C19: bool | D19: PC | E19: true
A20: usuarios/{id_usuario} | B20: medidores | C20: array<string> | D20: PC | E20: ["000100", "003200"] | F20: Solo los medidores activos.
A21: mes_aaaa-mm/{id_usuario} | B21: (ID del documento) | C21: string | D21: PC | E21: Igual al id_usuario | F21: Una colección nueva cada mes (mes_2026-09). Es la tabla del mes.
A22: mes_aaaa-mm/{id_usuario} | B22: nro_conexion, nombre, sector, direccion, codigo_categoria | C22: string | D22: PC | E22: copia del padrón | F22: La crea la PC al abrir el mes; así la app de lectura no consulta usuarios.
A23: mes_aaaa-mm/{id_usuario} | B23: medidores | C23: array<map> | D23: PC crea · Lector completa | E23: [{nro_medidor:"000100", lectura_anterior:120, fecha_anterior:"2026-08-07", lectura_actual:131, fecha_lectura:"2026-09-07", novedad:""}] | F23: Una entrada por medidor.
A24: mes_aaaa-mm/{id_usuario} | B24: consumo_total_m3 | C24: number | D24: App del lector | E24: 15 | F24: Suma de los consumos.
A25: mes_aaaa-mm/{id_usuario} | B25: historial_m3 | C25: array<number> | D25: PC | E25: [4, 5, 9, 12, 16] | F25: 5 consumos de meses anteriores. El histograma usa estos 5 más el consumo actual: no hace falta leer meses viejos.
A26: mes_aaaa-mm/{id_usuario} | B26: nro_recibo, monto_agua, monto_desague, cargo_fijo, deuda_anterior, igv, redondeo, total_a_pagar, meses_adeudados | C26: string / number | D26: PC al generar recibos | E26: 000058392 · 22.00 · 0.00 · 1.50 · 0.00 · 0.00 · 0.00 · 23.50 · 1 | F26: Quedan vacíos hasta generar los recibos.
A27: mes_aaaa-mm/{id_usuario} | B27: monto_pagado, fecha_pago | C27: number / string | D27: Secretaria (PC) | E27: 0 · null | F27: Al marcar pagado: monto_pagado = total_a_pagar.
A29: Consultas que hace cada parte
A30: Quién | B30: Qué hace | C30: Lecturas de documentos
A31: App del lector | B31: Cargar su sector: mes_aaaa-mm donde sector == S (una vez; luego queda en caché sin conexión) | C31: Los usuarios del sector (máx. 338)
A32: App del lector | B32: Guardar una lectura: update de un documento | C32: 0 lecturas, 1 escritura
A33: PC | B33: Abrir el mes: leer usuarios y el mes anterior; crear los documentos del mes | C33: 2 × usuarios lecturas, 1 × usuarios escrituras
A34: PC | B34: Generar recibos: calcular y escribir los campos del recibo | C34: Usa lo ya cargado, 1 × usuarios escrituras
A35: PC | B35: Cobros: cargar el mes una vez al abrir el programa y trabajar en memoria; marcar pagado = update de un documento | C35: 1 × usuarios lecturas por sesión
A36: PC | B36: Respaldo Excel del mes: se arma con los datos ya cargados | C36: 0 lecturas extra
A37: PC | B37: Corregir un DNI: crear el documento con el ID correcto, copiar, borrar el anterior (en usuarios y en cada mes) | C37: Pocas operaciones; ocurre rara vez

Sheet Mes_ejemplo
A1: Tabla del mes y Excel de respaldo (formato)
A2: Una hoja por sector, igual que tu Excel actual, con las columnas de recibo y pago a la derecha. Una persona con 2 medidores ocupa 2 filas; los datos de recibo y pago van en la primera. Filas 2 y 3: ejemplos ficticios.
A4: Fecha de lectura | B4: Número de conexión | C4: Número de medidor | D4: Beneficiario | E4: Dirección | F4: Lectura anterior | G4: Lectura actual | H4: Consumo (m³) | I4: Recibo N° | J4: Deuda anterior | K4: Total a pagar | L4: Meses adeudados | M4: Pagado | N4: Fecha de pago
A5: 2026-09-07 | B5: 000796 | C5: 22392996 | D5: ALVAREZ CHUQUIYANQUI, MARIBEL NAYELI | E5: AUCAYPATA S/N | F5: 58 | G5: 80 | H5: =IF(G5="","",G5-F5) -> 22 | I5: 000058392 | J5: 0 | K5: 23.5 | L5: 1 | M5: 23.5 | N5: 2026-09-12
A6: 2026-09-07 | B6: 000123 | C6: 000100 | D6: EJEMPLO QUISPE, JUAN (ficticio) | E6: CHAUPI S/N | F6: 120 | G6: 131 | H6: =IF(G6="","",G6-F6) -> 11 | I6: 000058393 | J6: 18.5 | K6: 35 | L6: 2 | M6: 0
A7: 2026-09-07 | B7: 000123 | C7: 003200 | D7: EJEMPLO QUISPE, JUAN (ficticio) | E7: CHAUPI S/N | F7: 55 | G7: 59 | H7: =IF(G7="","",G7-F7) -> 4
A9: Totales del ejemplo
A10: Consumo total (m³) | H10: =SUM(H5:H7) -> 37
A11: Total a pagar | K11: =SUM(K5:K7) -> 58.5

Sheet Uso_gratuito
A1: ¿Cabe en el plan gratuito de Firebase (Spark)?
A2: Azul = dato editable. Límites diarios de Firestore del plan gratuito según la página de precios de Google Cloud.
A4: Datos de partida
A5: Usuarios (documentos por mes) | B5: 800 | E5: Tu cifra. Hoy hay 766 activos.
A6: Sesiones de la secretaria al mes (cargan el mes completo) | B6: 20 | E6: Una por día de trabajo aproximadamente.
A7: Tamaño promedio de un documento mensual (bytes) | B7: 900 | E7: Estimado con 1 a 3 medidores y el histograma.
A9: Límites diarios gratuitos
A10: Lecturas de documentos por día | B10: 50000 | E10: Cuota gratuita de Firestore.
A11: Escrituras por día | B11: 20000
A12: Almacenamiento total (MB) | B12: 1024 | E12: 1 GiB.
A14: Operaciones por mes
A15: Actividad | B15: Lecturas | C15: Escrituras | E15: Nota
A16: Abrir el mes (leer padrón y mes anterior, crear documentos) | B16: =2*B5 -> 1600 | C16: =B5 -> 800 | E16: Una vez al mes.
A17: Lecturas en campo (cada lector carga su sector y guarda) | B17: =B5 -> 800 | C17: =B5 -> 800 | E17: La app guarda en caché; guardar una lectura es 1 escritura.
A18: Generar recibos | B18: =B5 -> 800 | C18: =B5 -> 800 | E18: Peor caso: sin usar lo ya cargado.
A19: Cobros y consultas de la secretaria | B19: =B6*B5 -> 16000 | C19: =B5 -> 800 | E19: Peor caso: todos pagan.
A20: Total del mes | B20: =SUM(B16:B19) -> 19200 | C20: =SUM(C16:C19) -> 3200
A21: Promedio por día (30 días) | B21: =B20/30 -> 640 | C21: =C20/30 -> 106.66667
A23: Día más pesado (abrir mes + generar recibos + una sesión de cobros)
A24: Lecturas ese día | B24: =B16+B18+B5 -> 3200
A25: Escrituras ese día | B25: =C16+C18 -> 1600
A26: Porcentaje del límite diario de lecturas | B26: =B24/B10 -> 0.064
A27: Porcentaje del límite diario de escrituras | B27: =B25/B11 -> 0.08
A29: Almacenamiento
A30: MB por mes | B30: =B5*B7/1048576 -> 0.68664551
A31: MB por año | B31: =B30*12 -> 8.2397461
A32: Años hasta llenar 1 GiB | B32: =B12/B31 -> 124.27567 | E32: Sin contar el padrón, que es muy pequeño.

Sheet Reglas_negocio
A1: Reglas, supuestos y pendientes
A2: Tipo: Regla (decidida), Supuesto (asumido, corregible), Pendiente (necesita confirmación).
A4: N° | B4: Tipo | C4: Área | D4: Descripción | E4: Campos
A5: 1 | B5: Regla | C5: Códigos | D5: El número de medidor es también su ID. Mínimo 6 dígitos con ceros adelante: 100 → 000100, 3200 → 003200, 990991 → 990991. Si ya tiene 6 o más dígitos no se cambia. | E5: medidor.nro_medidor
A6: 2 | B6: Regla | C6: Códigos | D6: Una persona tiene un solo código de conexión (6 dígitos) aunque tenga varios medidores. El recibo es uno por persona y suma el consumo de todos sus medidores. | E6: usuario.nro_conexion, recibo
A7: 3 | B7: Regla | C7: Códigos | D7: id_usuario es el DNI con 8 dígitos y ceros adelante (7654321 → 07654321). | E7: usuario.id_usuario
A8: 4 | B8: Regla | C8: Códigos | D8: Si el mismo DNI aparece en personas distintas, ambas llevan sufijo: 07654321-1 y 07654321-2. Una misma persona con varios medidores no cuenta como repetida. | E8: usuario.id_usuario
A9: 5 | B9: Regla | C9: Códigos | D9: Si una persona o institución no tiene DNI ni RUC, recibe un ID provisional SD-001, SD-002, etc. | E9: usuario.id_usuario
A10: 6 | B10: Regla | C10: Códigos | D10: Un ID con guion hace que el programa avise: pedir el DNI a las personas y corregirlo. Al corregir, el programa crea el documento con el ID correcto, copia los datos, borra el anterior y lo renombra también en los meses. | E10: usuarios, mes_aaaa-mm
A11: 7 | B11: Regla | C11: Mes | D11: Cada mes se crea una colección nueva (mes_aaaa-mm) con un documento por usuario. Es la tabla del mes, igual al Excel de lecturas. | E11: periodo, lectura, recibo
A12: 8 | B12: Regla | C12: Mes | D12: Al abrir el mes, el programa copia el padrón, pone lectura_anterior = lectura_actual y fecha_anterior = fecha_lectura del mes pasado, y deja la actual vacía. | E12: lectura
A13: 9 | B13: Regla | C13: Lecturas | D13: Si lectura_actual es menor que lectura_anterior, la app pide una novedad (por ejemplo CAMBIO DE MEDIDOR) y permite corregir el consumo. | E13: lectura.novedad, lectura.consumo_m3
A14: 10 | B14: Regla | C14: Facturación | D14: monto_agua = consumo × precio del rango. El desagüe es constante por categoría y el cargo fijo es editable por el dueño. | E14: recibo, categoria, rango_tarifa
A15: 11 | B15: Regla | C15: Facturación | D15: total_a_pagar = agua + desagüe + cargo fijo + deuda_anterior + IGV − redondeo. El redondeo resta las centésimas (17.56 queda en 17.50). El IGV es 0.00 si IGV_ACTIVO es falso. | E15: recibo
A16: 12 | B16: Regla | C16: Deuda | D16: deuda_anterior = MAX(0, total_a_pagar anterior − monto_pagado anterior). Como el total anterior ya incluye su propia deuda, se acumula mes a mes sin sumar recibos viejos. | E16: recibo.deuda_anterior
... A30: 26 | B30: Pendiente | C30: DNI | D30: Tres DNI tienen 9 dígitos: revisar si son errores de digitación o documentos distintos. | E30: usuario.id_usuario

Sheet Migracion_datos
A1: Qué hay que ordenar al importar tus Excel
A2: Conteos de LISTA_DE_USUARIOS_2026.xlsx y RELACION_DE_USUARIOS_DEL_CAAPD.xlsx, aplicando las reglas nuevas.
A4: Indicador | B4: Valor | C4: Qué se hace
A5: Filas en la lista de usuarios | B5: 808 | C5: 766 activos, 41 inactivos y 1 con el estado mal escrito (NACTIVO).
A6: Usuarios ACTIVOS (medidores que se importan) | B6: 766 | C6: Solo se importan los activos.
A7: Personas distintas entre los activos (DNI + nombre) | B7: 714 | C7: Cada persona queda como un usuario con una lista de medidores.
A8: Personas con un solo medidor | B8: 664
A9: Personas con 2 o 3 medidores | B9: =B7-B8 -> 50 | C9: Un solo código de conexión y un solo recibo.
A10: Personas que hoy tienen más de un código de conexión | B10: 49 | C10: Unificar: se conserva un código (propongo el menor).
A11: DNI compartidos por personas distintas | B11: 22 | C11: Afecta a 48 personas: reciben -1, -2 y quedan pendientes de corregir.
A12: Personas sin DNI | B12: 25 | C12: Reciben ID provisional SD-001, SD-002... y quedan pendientes.
A13: DNI de 7 dígitos (activos) | B13: 31 | C13: Se les agrega un cero adelante hasta llegar a 8.
A14: DNI de 9 dígitos (activos) | B14: 3 | C14: Revisar a mano.
A15: Medidores activos con menos de 6 dígitos | B15: 3 | C15: 9174 → 009174, 10085 → 010085, 3386 → 003386. El resto ya tiene 6 o más dígitos y no cambia.
A16: Números de medidor repetidos entre activos | B16: 2 | C16: 24261109 está en dos personas distintas y 25097679 en dos filas de la misma persona (duplicado a eliminar).
A17: Activos sin código de conexión en el Excel de lecturas | B17: 2 | C17: Medidores 24345520 y 24345518: asignarles un código nuevo.
A18: Conexión sin medidor (000771) | B18: 1 | C18: Queda como usuario sin medidores (solo cargo fijo).
A19: Consumos negativos en el Excel de lecturas | B19: 14 | C19: Revisar si fueron cambios de medidor; la app pedirá novedad.
A20: Consumos en cero | B20: 161 | C20: Se factura solo el cargo fijo.
A21: Consumos mayores a 100 m³ | B21: 9 | C21: El histograma tiene eje dinámico.
A23: Usuarios activos por sector
A24: BARRIO DE CHAUPI | B24: 338 | C24: Documentos que carga el lector de ese sector.
A25: BARRIO DE PACHAYZA | B25: 308 | C25: Documentos que carga el lector de ese sector.
A26: BARRIO DE LUCMANI | B26: 68 | C26: Documentos que carga el lector de ese sector.
A27: HUAQUILLO | B27: 41 | C27: Documentos que carga el lector de ese sector.
A28: CHAUPICERCA | B28: 6 | C28: Documentos que carga el lector de ese sector.
A29: AYACUCHO | B29: 5 | C29: Documentos que carga el lector de ese sector.
A30: Total medidores activos | B30: =SUM(B24:B29) -> 766
