Workbook

Sheet RECIBOS
A3: FECHA DE PAGO | B3: N° CONEXIÓN | C3: N° MEDIDOR | D3: BARRIO | E3: BENEFICIARIO | F3: Dirección | G3: lect. Ant | I3: lect. Actual | J3: MESES | K3: CANT. MES | L3: MONTO | M3: TOTAL - DIA
A4: 46174 | B4: 000779 | C4: 20209138 | D4: CHAUPI | E4: NEYRA SIVINCHA, NORMA YSABEL | F4: LUCMANI S/N | J4: abril-mayo | K4: 2 | L4: 32
A5: 46174 | B5: 000079 | C5: 6658956 | D5: HUAQUILLO | E5: NEYRA SIVINCHA, NORMA YSABEL | F5: HUAQUILLO S/N | J5: abril-mayo | K5: 2 | L5: 28 | P5: 000527 | Q5: 2001887 | R5: AYACUCHO | S5: CHAUCAYANQUI ALVAREZ,CARLOS ALEJO | T5: S/N
A6: 46174 | B6: 000607 | C6: 190005356 | D6: PACHAYZA | E6: TORRES CABRERA MERY | F6: CALLE SOLEDAD | J6: marzo-abril-mayo | K6: 3 | L6: 92 | P6: 000528 | Q6: 6593681 | R6: AYACUCHO | S6: CHAUCAYANQUI ALVAREZ,CLEMENTE | T6: S/N
A7: 46174 | B7: 000171 | C7: 6585525 | D7: PACHAYZA | E7: I.E. ANDRES AVELINO CACERES | F7: SECTOR PACHAYZA - PARTE ALTA | J7: febrero/mayo | K7: 4 | L7: 99 | P7: 000529 | Q7: 220014925 | R7: AYACUCHO | S7: SURCO VILLENA,SUSY BETTY | T7: S/N
A8: 46174 | B8: 000172 | C8: 6578765 | D8: PACHAYZA | E8: I.E. ANDRES AVELINO CACERES | F8: SECTOR PACHAYZA-PARTE ALTA | J8: febrero/mayo | K8: 4 | L8: 65 | P8: 000530 | Q8: 6563926 | R8: AYACUCHO | S8: TORRES COA,CILA CAMILA | T8: S/N
A9: 46174 | B9: 000696 | C9: 21130896 | D9: PACHAYZA | E9: HUAMANI CHALCO GENOVEVA ESTELITA | F9: SECTOR PUCRO | J9: abril-mayo | K9: 2 | L9: 18 | P9: 000531 | Q9: 6563939 | R9: AYACUCHO | S9: TORRES HUAMANI,AMELIA BENITA | T9: S/N
A10: 46174 | B10: 000199 | C10: 101745489 | D10: PACHAYZA | E10: NAVINTA CORIMANYA, VICO NICOLAS | F10: SECTOR PACHAYZA - PARTE ALTA | J10: mayo | K10: 1 | L10: 5 | P10: 000704 | Q10: 220017513 | R10: CHAUPICERCA | S10: CASTRO USCAMAYTA ELIANA | T10: CHAUPICERCA S/N
A11: 46174 | B11: 000236 | C11: 135304 | D11: PACHAYZA | E11: TORRES MONTALVO ,SONIA YENI | F11: SECTOR PACHAYZA - PARTE ALTA | J11: mayo | K11: 1 | L11: 10.5 | P11: 000534 | Q11: 6593461 | R11: CHAUPICERCA | S11: NEYRA DE USCAMAYTA,MANUELA ANA | T11: CHAUPI CERCA S/N
A12: 46174 | B12: 000305 | C12: 6577360 | D12: CHAUPI | E12: CHALCO TORRES ,JUANA | F12: PASAJE EL OLVIDO S/N | J12: abril-mayo | K12: 2 | L12: 10 | P12: 000533 | Q12: 6593433 | R12: CHAUPICERCA | S12: ROMERO CHAUCAYANQUI JUSTO MARCELO | T12: CHAUPI CERCA S/N
A13: 46174 | B13: 000453 | C13: 60061357 | D13: CHAUPI | E13: RAMIREZ CHAUCAYANQUI ,SILVIO HUILE | F13: CALLE 28 DE JULIO S/N | J13: abril-mayo | K13: 2 | L13: 10 | P13: 000535 | Q13: 6563916 | R13: CHAUPICERCA | S13: USCAMAYTA ALCA ,CILA | T13: CHAUPI CERCA S/N
A14: 46174 | B14: 000720 | C14: 220017512 | D14: PACHAYZA | E14: RAMIREZ CHAUCAYANQUI, ROSA ALEJANDRINA | F14: PACHAYZA-PARTE ALTA | J14: mayo | K14: 1 | L14: 5 | P14: 000536 | Q14: 6593726 | R14: CHAUPICERCA | S14: USCAMAYTA NEYRA,DAVID JESUS | T14: CHAUPI CERCA S/N
A15: 46174 | B15: 000220 | C15: 6586825 | D15: PACHAYZA | E15: RAMIREZ CHAUCAYANQUI ZENON ROMULO | F15: SECTOR PACHAYZA - PARTE ALTA | J15: mayo | K15: 1 | L15: 5 | P15: 000537 | Q15: 6593657 | R15: CHAUPICERCA | S15: VERA REVILLA ,MANUEL | T15: CHAUPI CERCA S/N
A16: 46174 | B16: 000724 | C16: 220017314 | D16: PACHAYZA | E16: RAMIREZ CHAUCAYANQUI, ZENON ROMULO | F16: SECTOR PACHAYZA - HUERTA | J16: mayo | K16: 1 | L16: 5 | P16: 000796 | Q16: 22392996 | R16: LUCMANI | S16: ALVAREZ CHUQUIYANQUI, MARIBEL NAYELI | T16: AUCAYPATA S/N
... A28: 46174 | B28: 000352 | C28: 6577458 | D28: CHAUPI | E28: GONSALES PALOMINO ,ADOLFO PEDRO | F28: PASAJE LA SALLE S/N | J28: mayo | K28: 1 | L28: 5 | P28: 000010 | Q28: 6659780 | R28: LUCMANI | S28: CHALCO ESCOBAR,REYNA | T28: LUCMANI S/N
A29: 46174 | B29: 000656 | C29: 21006534 | D29: PACHAYZA | E29: ALFARO ESCOBAR EDWIN YHON | F29: PACHAYZA-PARTE BAJA | J29: mayo | K29: 1 | L29: 14.5 | M29: =SUM(L4:L29) -> 506 | P29: 000011 | Q29: 6659782 | R29: LUCMANI | S29: CHALCO ESCOBAR,TOMAS | T29: LUCMANI S/N
A30: 46175 | B30: 000735 | C30: 23022723 | D30: PACHAYZA | E30: COA TORRES, ALEXANDER REY | F30: SECTOR TARAPATA | J30: septiembre/mayo | K30: 9 | L30: 45 | P30: 000669 | Q30: 21003048 | R30: LUCMANI | S30: CHAVEZ ANTACHOQUE HENRRY | T30: SECTOR JENCHO
A31: 46175 | B31: 000202 | C31: 23022177 | D31: PACHAYZA | E31: NEYRA TORRES, ELIZABETH YENY | F31: SECTOR PACHAYZA - PARTE BAJA | J31: abril-mayo | K31: 2 | L31: 97 | P31: 000012 | Q31: 21130894 | R31: LUCMANI | S31: CHUQUIYANQUI CHALCO,ELIDA | T31: LUCMANI S/N
A32: 46175 | B32: 000101 | C32: 6564131 | D32: PACHAYZA | E32: CASTRO CORIMANYA,ANDREA | F32: SECTOR PACHAYZA - TARAPATA | J32: abril-mayo | K32: 2 | L32: 13.5 | P32: 000013 | Q32: 21003043 | R32: LUCMANI | S32: CHUQUIYANQUI HUAMANI,ETELVINA VILMA | T32: LUCMANI S/N
A33: 46175 | B33: 000446 | C33: 60062060 | D33: CHAUPI | E33: PUGA HUAHUACONDO ,FRANKLIN | F33: LUCMANI S/N | J33: abril-mayo | K33: 2 | L33: 89 | P33: 000014 | Q33: 6578450 | R33: LUCMANI | S33: CORIMANYA DE ARUTAYPE ,SUNILDA MAGDALENA | T33: LUCMANI S/N
A34: 46175 | B34: 000262 | C34: 6584520 | D34: PACHAYZA | E34: VEGA HUAMANI , LORENZA | F34: SECTOR PACHAYZA - PARTE BAJA | J34: mayo | K34: 1 | L34: 10.5 | P34: 000686 | Q34: 200031259 | R34: LUCMANI | S34: ESCOBAR ANTACHOQUE SOLEDAD | T34: LUCMANI S/N
A35: 46175 | B35: 000600 | C35: 190005359 | D35: PACHAYZA | E35: CASTRO CORIMANYA WALTER | F35: PACHAYZA - ALTA | J35: mayo | K35: 1 | L35: 20.5 | P35: 000684 | Q35: 200031254 | R35: LUCMANI | S35: ESCOBAR CHUQUIYANQUI LISBET NATALI | T35: SECTOR GABINAYOC
A36: 46175 | B36: 000633 | C36: 200039364 | D36: PACHAYZA | E36: TORRES VEGA NILA LIZETH | F36: PACHAYZA-PARTE BAJA | J36: mayo | K36: 1 | L36: 13.5 | P36: 000548 | Q36: 09092433 | R36: LUCMANI | S36: ESCOBAR MANCILLA WALTER | T36: AUCAYPATA
A37: 46175 | B37: 000599 | C37: 19003898 | D37: CHAUPI | E37: USCAMAITA CHAVEZ, OTO LUDWIN | F37: CHAUPI | J37: mayo | K37: 1 | L37: 5 | P37: 000017 | Q37: 6582818 | R37: LUCMANI | S37: ESCOBAR MONTALVO CELSO CELESTINO | T37: LUCMANI S/N
A38: 46175 | B38: 000073 | C38: 23015476 | D38: HUAQUILLO | E38: HUAMANI MONTALVO,ROSARIO RUPERTA | F38: HUAQUILLO S/N | J38: mayo | K38: 1 | L38: 5 | P38: 000685 | Q38: 200031244 | R38: LUCMANI | S38: FLORES QUISPE ROSA | T38: SECTOR GABINAYOC
A39: 46175 | B39: 000528 | C39: 6593681 | D39: AYACUCHO | E39: CHAUCAYANQUI ALVAREZ,CLEMENTE | F39: S/N | J39: mayo | K39: 1 | L39: 6.5 | P39: 000631 | Q39: 200039369 | R39: LUCMANI | S39: GUTIERREZ CHALCO RANULFO | T39: CALLE LUCMANI
A40: 46175 | B40: 000670 | C40: 21003051 | D40: CHAUPI | E40: VERA MONTALVO DE NAVINTA APOLONIA | F40: CALLE 28 DE JULIO | J40: abril-mayo | K40: 2 | L40: 14 | P40: 000691 | Q40: 21000863 | R40: LUCMANI | S40: GUTIERREZ CHALCO REYNALDO ROBERTO | T40: LUCMANI S/N
A41: 46175 | B41: 000273 | C41: 6590427 | D41: CHAUPI | E41: RAMIREZ CHAUCAYANQUI VITALIA LUZ | F41: CALLE 05 DE AGOSTO S/N | J41: mayo | K41: 1 | L41: 59.5 | P41: 000019 | Q41: 6590708 | R41: LUCMANI | S41: GUZMAN CHAUCAYANQUI ,NANCY | T41: LUCMANI S/N
A42: 46175 | B42: 000723 | C42: 220017571 | D42: PACHAYZA | E42: ALVAREZ RAMIREZ, KEVIN JHASMANY | F42: SECTOR PACHAYZA - HUERTA | J42: mayo | K42: 1 | L42: 14.5 | P42: 000020 | Q42: 6579093 | R42: LUCMANI | S42: HUAMANI CANDELARIA | T42: LUCMANI S/N
A43: 46175 | B43: 791 | C43: 20520454 | D43: PACHAYZA | E43: NEYRA RAMIREZ,WASHINTON LUIGI | F43: PACHAYZA-PUCRO S/N | J43: mayo | K43: 1 | L43: 5 | P43: 000021 | Q43: 6579096 | R43: LUCMANI | S43: HUAMANI CARPIO,CIRILO | T43: LUCMANI S/N
A44: 46175 | B44: 000697 | C44: 220017509 | D44: PACHAYZA | E44: CORIMANYA YGNACIO, YASSER RENE | F44: PACHAYZA-PARTE ALTA | J44: mayo | K44: 1 | L44: 14.5 | P44: 000022 | Q44: 6590942 | R44: LUCMANI | S44: HUAMANI COA ,FIDELA CARMEN | T44: LUCMANI S/N
A45: 46175 | B45: 000536 | C45: 6593726 | D45: CHAUPICERCA | E45: USCAMAYTA NEYRA,DAVID JESUS | F45: CHAUPI CERCA S/N | J45: mayo | K45: 1 | L45: 5 | P45: 000023 | Q45: 21000864 | R45: LUCMANI | S45: HUAMANI COA,LUCIO INGNACIO | T45: LUCMANI S/N
A46: 46175 | B46: 000534 | C46: 6593461 | D46: CHAUPICERCA | E46: NEYRA DE USCAMAYTA,MANUELA ANA | F46: CHAUPI CERCA S/N | J46: mayo | K46: 1 | L46: 5 | M46: =SUM(L30:L46) -> 423 | P46: 000589 | Q46: 200005311 | R46: LUCMANI | S46: HUAMANI LUQUE CLEDY | T46: LUCMANI S/N
A47: 46176 | B47: 000174 | C47: 23022179 | D47: PACHAYZA | E47: LAZARO USCAMAYTA CIRO | F47: SECTOR PACHAYZA - PARTE BAJA | J47: marzo-abril-mayo | K47: 3 | L47: 15 | P47: 000703 | Q47: 23015475 | R47: LUCMANI | S47: HUAMANI MALVA MARIA | T47: LUCMANI S/N
A48: 46176 | B48: 000645 | C48: 200005302 | D48: PACHAYZA | E48: MONTALVO NEYRA SUSY EVELIN | F48: PACHAYZA-PARTE BAJA | J48: mayo | K48: 1 | L48: 5 | P48: 000025 | Q48: 6593473 | R48: LUCMANI | S48: HUAMANI TORRES CORINA VALERIANA | T48: LUCMANI S/N
A49: 46176 | B49: 000287 | C49: 60061416 | D49: CHAUPI | E49: CARPIO ARROYO ,BERTILDA | F49: CALLE CUYO CUYO S/N | J49: abril-mayo | K49: 2 | L49: 45 | P49: 000027 | Q49: 6587948 | R49: LUCMANI | S49: HUAMANI USCAMAYTA,MELITON GABRIEL | T49: LUCMANI S/N
A50: 46176 | B50: 000316 | C50: 60062520 | D50: CHAUPI | E50: CHAVEZ USCAMAYTA ,JACINTO | F50: CALLE CUYO CUYO S/N | J50: mayo | K50: 1 | L50: 5 | P50: 000035 | Q50: 6585587 | R50: LUCMANI | S50: ILATAYPE MANSILLA ABEL MARCO | T50: LUCMANI S/N
A51: 46176 | B51: 000663 | C51: 200005306 | D51: PACHAYZA | E51: CHAVEZ ALLCA OLIVA CLORENTINA | F51: PACHAYZA-PARTE BAJA | J51: mayo | K51: 1 | L51: 12.5 | P51: 000028 | Q51: 23015478 | R51: LUCMANI | S51: LOPEZ CHALCO,BETTY MARIA | T51: LUCMANI S/N
A52: 46176 | B52: 000390 | C52: 6577445 | D52: CHAUPI | E52: HUAMANI USCAMAITA ,HIPOLITO | F52: CALLE LOS ESTUDIANTES S/N | J52: mayo | K52: 1 | L52: 12.5 | P52: 000029 | Q52: 6572058 | R52: LUCMANI | S52: LOPEZ MANCILLA,GLORIA | T52: LUCMANI S/N
A53: 46176 | B53: 000773 | C53: 22392997 | D53: PACHAYZA | E53: VILCA MAMANI ,DELIA | F53: PACHAYZA - PUCRO | J53: mayo | K53: 1 | L53: 25.5 | M53: =SUM(L47:L53) -> 120.5 | P53: 000030 | Q53: 6578558 | R53: LUCMANI | S53: LUQUE ARUTAYPE, JOSEFA ANGELITA | T53: LUCMANI S/N
...

Sheet CAJA
C3: CAJA MES DE JUNIO DEL 2025
A6: FECHA | B6: INGRESO RECIBOS | C6: INGRESOS VARIABLES | D6: GRIFO DE AGUA | E6: INGRESOS MULTAS | F6: VENTA DE ACCESORIOS | G6: MOVILIDAD PETAR | H6: EGRESO TOTAL | I6: SALDO TOTAL
A7: 46174 | B7: =SUMIFS(RECIBOS!$L$4:$L$822,RECIBOS!$A$4:$A$822,CAJA!A7) -> 506 | C7: =SUMIFS(INGRESOS!$F$13:$F$33,INGRESOS!$B$13:$B$33,CAJA!A7) -> 1071 | D7: =SUMIFS(INGRESOS!$F$39:$F$155,INGRESOS!$B$39:$B$155,CAJA!A7) -> 150 | E7: =SUMIFS(INGRESOS!$F$161:$F$165,INGRESOS!$B$161:$B$165,CAJA!A7) -> 0 | F7: {=SUMIFS(INGRESOS!F170:F188,INGRESOS!B170:B188,CAJA!A7:A37)} -> 0 | G7: =SUMIFS(EGRESOS!$F$85:$F$100,EGRESOS!$B$85:$B$100,CAJA!A7) -> 0 | H7: =SUMIFS(EGRESOS!$F$4:$F$77,EGRESOS!$B$4:$B$77,CAJA!A7) -> 114.4 | I7: =(B7+C7+D7+F7)-H7 -> 1612.6
A8: 46175 | B8: =SUMIFS(RECIBOS!$L$4:$L$822,RECIBOS!$A$4:$A$822,CAJA!A8) -> 423 | C8: =SUMIFS(INGRESOS!$F$13:$F$33,INGRESOS!$B$13:$B$33,CAJA!A8) -> 0 | D8: =SUMIFS(INGRESOS!$F$39:$F$155,INGRESOS!$B$39:$B$155,CAJA!A8) -> 160 | E8: =SUMIFS(INGRESOS!$F$161:$F$165,INGRESOS!$B$161:$B$165,CAJA!A8) -> 0 | F8: 0 | G8: =SUMIFS(EGRESOS!$F$85:$F$100,EGRESOS!$B$85:$B$100,CAJA!A8) -> 0 | H8: =SUMIFS(EGRESOS!$F$4:$F$77,EGRESOS!$B$4:$B$77,CAJA!A8) -> 0 | I8: =(I7+B8+C8+D8+H8+F8)-H8 -> 2195.6
A9: 46176 | B9: =SUMIFS(RECIBOS!$L$4:$L$822,RECIBOS!$A$4:$A$822,CAJA!A9) -> 120.5 | C9: =SUMIFS(INGRESOS!$F$13:$F$33,INGRESOS!$B$13:$B$33,CAJA!A9) -> 0 | D9: =SUMIFS(INGRESOS!$F$39:$F$155,INGRESOS!$B$39:$B$155,CAJA!A9) -> 190 | E9: =SUMIFS(INGRESOS!$F$161:$F$165,INGRESOS!$B$161:$B$165,CAJA!A9) -> 0 | F9: 0 | G9: =SUMIFS(EGRESOS!$F$85:$F$100,EGRESOS!$B$85:$B$100,CAJA!A9) -> 0 | H9: =SUMIFS(EGRESOS!$F$4:$F$77,EGRESOS!$B$4:$B$77,CAJA!A9) -> 825 | I9: =(I8+B9+C9+D9+H9+F9)-H9 -> 2506.1
A10: 46177 | B10: =SUMIFS(RECIBOS!$L$4:$L$822,RECIBOS!$A$4:$A$822,CAJA!A10) -> 275 | C10: =SUMIFS(INGRESOS!$F$13:$F$33,INGRESOS!$B$13:$B$33,CAJA!A10) -> 135 | D10: =SUMIFS(INGRESOS!$F$39:$F$155,INGRESOS!$B$39:$B$155,CAJA!A10) -> 180 | E10: =SUMIFS(INGRESOS!$F$161:$F$165,INGRESOS!$B$161:$B$165,CAJA!A10) -> 0 | F10: 0 | G10: =SUMIFS(EGRESOS!$F$85:$F$100,EGRESOS!$B$85:$B$100,CAJA!A10) -> 0 | H10: =SUMIFS(EGRESOS!$F$4:$F$77,EGRESOS!$B$4:$B$77,CAJA!A10) -> 0 | I10: =(I9+B10+C10+D10+F10)-H10 -> 3096.1
A11: 46178 | B11: =SUMIFS(RECIBOS!$L$4:$L$822,RECIBOS!$A$4:$A$822,CAJA!A11) -> 396 | C11: =SUMIFS(INGRESOS!$F$13:$F$33,INGRESOS!$B$13:$B$33,CAJA!A11) -> 0 | D11: =SUMIFS(INGRESOS!$F$39:$F$155,INGRESOS!$B$39:$B$155,CAJA!A11) -> 140 | E11: =SUMIFS(INGRESOS!$F$161:$F$165,INGRESOS!$B$161:$B$165,CAJA!A11) -> 0 | F11: 0 | G11: =SUMIFS(EGRESOS!$F$85:$F$100,EGRESOS!$B$85:$B$100,CAJA!A11) -> 0 | H11: =SUMIFS(EGRESOS!$F$4:$F$77,EGRESOS!$B$4:$B$77,CAJA!A11) -> 42.5 | I11: =(I10+B11+C11+D11+F11)-H11 -> 3589.6
A12: 46179 | B12: =SUMIFS(RECIBOS!$L$4:$L$822,RECIBOS!$A$4:$A$822,CAJA!A12) -> 214.5 | C12: =SUMIFS(INGRESOS!$F$13:$F$33,INGRESOS!$B$13:$B$33,CAJA!A12) -> 8.5 | D12: =SUMIFS(INGRESOS!$F$39:$F$155,INGRESOS!$B$39:$B$155,CAJA!A12) -> 90 | E12: =SUMIFS(INGRESOS!$F$161:$F$165,INGRESOS!$B$161:$B$165,CAJA!A12) -> 0 | F12: 0 | G12: =SUMIFS(EGRESOS!$F$85:$F$100,EGRESOS!$B$85:$B$100,CAJA!A12) -> 0 | H12: =SUMIFS(EGRESOS!$F$4:$F$77,EGRESOS!$B$4:$B$77,CAJA!A12) -> 0 | I12: =(I11+B12+C12+D12+F12)-H12 -> 3902.6
A13: 46180 | B13: =SUMIFS(RECIBOS!$L$4:$L$822,RECIBOS!$A$4:$A$822,CAJA!A13) -> 0 | C13: =SUMIFS(INGRESOS!$F$13:$F$33,INGRESOS!$B$13:$B$33,CAJA!A13) -> 0 | D13: =SUMIFS(INGRESOS!$F$39:$F$155,INGRESOS!$B$39:$B$155,CAJA!A13) -> 70 | E13: =SUMIFS(INGRESOS!$F$161:$F$165,INGRESOS!$B$161:$B$165,CAJA!A13) -> 0 | F13: 0 | G13: =SUMIFS(EGRESOS!$F$85:$F$100,EGRESOS!$B$85:$B$100,CAJA!A13) -> 0 | H13: =SUMIFS(EGRESOS!$F$4:$F$77,EGRESOS!$B$4:$B$77,CAJA!A13) -> 0 | I13: =(I12+B13+C13+D13+F13)-H13 -> 3972.6
A14: 46181 | B14: =SUMIFS(RECIBOS!$L$4:$L$822,RECIBOS!$A$4:$A$822,CAJA!A14) -> 359.5 | C14: =SUMIFS(INGRESOS!$F$13:$F$33,INGRESOS!$B$13:$B$33,CAJA!A14) -> 0 | D14: =SUMIFS(INGRESOS!$F$39:$F$155,INGRESOS!$B$39:$B$155,CAJA!A14) -> 130 | E14: =SUMIFS(INGRESOS!$F$161:$F$165,INGRESOS!$B$161:$B$165,CAJA!A14) -> 0 | F14: 0 | G14: =SUMIFS(EGRESOS!$F$85:$F$100,EGRESOS!$B$85:$B$100,CAJA!A14) -> 0 | H14: =SUMIFS(EGRESOS!$F$4:$F$77,EGRESOS!$B$4:$B$77,CAJA!A14) -> 1148.5 | I14: =(I13+B14+C14+D14+F14)-H14 -> 3313.6
A15: 46182 | B15: =SUMIFS(RECIBOS!$L$4:$L$822,RECIBOS!$A$4:$A$822,CAJA!A15) -> 652 | C15: =SUMIFS(INGRESOS!$F$13:$F$33,INGRESOS!$B$13:$B$33,CAJA!A15) -> 285 | D15: =SUMIFS(INGRESOS!$F$39:$F$155,INGRESOS!$B$39:$B$155,CAJA!A15) -> 80 | E15: =SUMIFS(INGRESOS!$F$161:$F$165,INGRESOS!$B$161:$B$165,CAJA!A15) -> 0 | F15: 0 | G15: =SUMIFS(EGRESOS!$F$85:$F$100,EGRESOS!$B$85:$B$100,CAJA!A15) -> 0 | H15: =SUMIFS(EGRESOS!$F$4:$F$77,EGRESOS!$B$4:$B$77,CAJA!A15) -> 1010 | I15: =(I14+B15+C15+D15+F15)-H15 -> 3320.6
A16: 46183 | B16: =SUMIFS(RECIBOS!$L$4:$L$822,RECIBOS!$A$4:$A$822,CAJA!A16) -> 204 | C16: =SUMIFS(INGRESOS!$F$13:$F$33,INGRESOS!$B$13:$B$33,CAJA!A16) -> 551 | D16: =SUMIFS(INGRESOS!$F$39:$F$155,INGRESOS!$B$39:$B$155,CAJA!A16) -> 40 | E16: =SUMIFS(INGRESOS!$F$161:$F$165,INGRESOS!$B$161:$B$165,CAJA!A16) -> 0 | F16: 0 | G16: =SUMIFS(EGRESOS!$F$85:$F$100,EGRESOS!$B$85:$B$100,CAJA!A16) -> 0 | H16: =SUMIFS(EGRESOS!$F$4:$F$77,EGRESOS!$B$4:$B$77,CAJA!A16) -> 490 | I16: =(I15+B16+C16+D16+F16)-H16 -> 3625.6
A17: 46184 | B17: =SUMIFS(RECIBOS!$L$4:$L$822,RECIBOS!$A$4:$A$822,CAJA!A17) -> 277.5 | C17: =SUMIFS(INGRESOS!$F$13:$F$33,INGRESOS!$B$13:$B$33,CAJA!A17) -> 150 | D17: =SUMIFS(INGRESOS!$F$39:$F$155,INGRESOS!$B$39:$B$155,CAJA!A17) -> 70 | E17: =SUMIFS(INGRESOS!$F$161:$F$165,INGRESOS!$B$161:$B$165,CAJA!A17) -> 0 | F17: 0 | G17: =SUMIFS(EGRESOS!$F$85:$F$100,EGRESOS!$B$85:$B$100,CAJA!A17) -> 0 | H17: =SUMIFS(EGRESOS!$F$4:$F$77,EGRESOS!$B$4:$B$77,CAJA!A17) -> 130 | I17: =(I16+B17+C17+D17+F17)-H17 -> 3993.1
A18: 46185 | B18: =SUMIFS(RECIBOS!$L$4:$L$822,RECIBOS!$A$4:$A$822,CAJA!A18) -> 656.5 | C18: =SUMIFS(INGRESOS!$F$13:$F$33,INGRESOS!$B$13:$B$33,CAJA!A18) -> 958 | D18: =SUMIFS(INGRESOS!$F$39:$F$155,INGRESOS!$B$39:$B$155,CAJA!A18) -> 100 | E18: =SUMIFS(INGRESOS!$F$161:$F$165,INGRESOS!$B$161:$B$165,CAJA!A18) -> 0 | F18: 0 | G18: =SUMIFS(EGRESOS!$F$85:$F$100,EGRESOS!$B$85:$B$100,CAJA!A18) -> 0 | H18: =SUMIFS(EGRESOS!$F$4:$F$77,EGRESOS!$B$4:$B$77,CAJA!A18) -> 2350 | I18: =(I17+B18+C18+D18+F18)-H18 -> 3357.6
A19: 46186 | B19: =SUMIFS(RECIBOS!$L$4:$L$822,RECIBOS!$A$4:$A$822,CAJA!A19) -> 93 | C19: =SUMIFS(INGRESOS!$F$13:$F$33,INGRESOS!$B$13:$B$33,CAJA!A19) -> 1113 | D19: =SUMIFS(INGRESOS!$F$39:$F$155,INGRESOS!$B$39:$B$155,CAJA!A19) -> 120 | E19: =SUMIFS(INGRESOS!$F$161:$F$165,INGRESOS!$B$161:$B$165,CAJA!A19) -> 0 | F19: 0 | G19: =SUMIFS(EGRESOS!$F$85:$F$100,EGRESOS!$B$85:$B$100,CAJA!A19) -> 0 | H19: =SUMIFS(EGRESOS!$F$4:$F$77,EGRESOS!$B$4:$B$77,CAJA!A19) -> 1320 | I19: =(I18+B19+C19+D19+F19)-H19 -> 3363.6
A20: 46187 | B20: =SUMIFS(RECIBOS!$L$4:$L$822,RECIBOS!$A$4:$A$822,CAJA!A20) -> 0 | C20: =SUMIFS(INGRESOS!$F$13:$F$33,INGRESOS!$B$13:$B$33,CAJA!A20) -> 0 | D20: =SUMIFS(INGRESOS!$F$39:$F$155,INGRESOS!$B$39:$B$155,CAJA!A20) -> 160 | E20: =SUMIFS(INGRESOS!$F$161:$F$165,INGRESOS!$B$161:$B$165,CAJA!A20) -> 0 | F20: 0 | G20: =SUMIFS(EGRESOS!$F$85:$F$100,EGRESOS!$B$85:$B$100,CAJA!A20) -> 0 | H20: =SUMIFS(EGRESOS!$F$4:$F$77,EGRESOS!$B$4:$B$77,CAJA!A20) -> 0 | I20: =(I19+B20+C20+D20+F20)-H20 -> 3523.6
A21: 46188 | B21: =SUMIFS(RECIBOS!$L$4:$L$822,RECIBOS!$A$4:$A$822,CAJA!A21) -> 486 | C21: =SUMIFS(INGRESOS!$F$13:$F$33,INGRESOS!$B$13:$B$33,CAJA!A21) -> 0 | D21: =SUMIFS(INGRESOS!$F$39:$F$155,INGRESOS!$B$39:$B$155,CAJA!A21) -> 250 | E21: =SUMIFS(INGRESOS!$F$161:$F$165,INGRESOS!$B$161:$B$165,CAJA!A21) -> 0 | F21: 0 | G21: =SUMIFS(EGRESOS!$F$85:$F$100,EGRESOS!$B$85:$B$100,CAJA!A21) -> 0 | H21: =SUMIFS(EGRESOS!$F$4:$F$77,EGRESOS!$B$4:$B$77,CAJA!A21) -> 65 | I21: =(I20+B21+C21+D21+F21)-H21 -> 4194.6
... A36: 46203 | B36: =SUMIFS(RECIBOS!$L$4:$L$822,RECIBOS!$A$4:$A$822,CAJA!A36) -> 0 | C36: =SUMIFS(INGRESOS!$F$13:$F$33,INGRESOS!$B$13:$B$33,CAJA!A36) -> 0 | D36: =SUMIFS(INGRESOS!$F$39:$F$155,INGRESOS!$B$39:$B$155,CAJA!A36) -> 170 | E36: =SUMIFS(INGRESOS!$F$161:$F$165,INGRESOS!$B$161:$B$165,CAJA!A36) -> 0 | F36: 0 | G36: =SUMIFS(EGRESOS!$F$85:$F$100,EGRESOS!$B$85:$B$100,CAJA!A36) -> 0 | H36: =SUMIFS(EGRESOS!$F$4:$F$77,EGRESOS!$B$4:$B$77,CAJA!A36) -> 4580 | I36: =(I35+B36+C36+D36+F36)-H36 -> 3295.1
B37: =SUMIFS(RECIBOS!$L$4:$L$822,RECIBOS!$A$4:$A$822,CAJA!A37) -> 0 | C37: =SUMIFS(INGRESOS!$F$13:$F$33,INGRESOS!$B$13:$B$33,CAJA!A37) -> 0 | D37: =SUMIFS(INGRESOS!$F$39:$F$155,INGRESOS!$B$39:$B$155,CAJA!A37) -> 0 | E37: =SUMIFS(INGRESOS!$F$161:$F$165,INGRESOS!$B$161:$B$165,CAJA!A37) -> 0 | F37: 0 | G37: =SUMIFS(EGRESOS!$F$85:$F$100,EGRESOS!$B$85:$B$100,CAJA!A37) -> 0 | H37: =SUMIFS(EGRESOS!$F$4:$F$77,EGRESOS!$B$4:$B$77,CAJA!A37) -> 0 | I37: =(I36+B37+C37+D37+F37)-H37 -> 3295.1
A38: SUMA TOTAL | B38: =SUM(B7:B37) -> 8875 | C38: =SUM(C7:C37) -> 4351.5 | D38: =SUM(D7:D37) -> 4230 | E38: =SUM(E7:E37) -> 0 | F38: =SUM(F7:F37) -> 0 | G38: =SUM(G7:G37) -> 0 | H38: =SUM(H7:H37) -> 14986.4 | I38: =I37 -> 3295.1
A40: COPIAS/IMPRESIONES | C40: 56 | K40: CAJA DE | L40: COPIAS
C42: =B38+C38+D38+E38+F38+C40 -> 17512.5 | G42: =G38 -> 0 | H42: =H38 -> 14986.4 | I42: =C42-H42-G42 -> 2526.1
C43: INGRESO TOTAL | H43: EGRESO TOTAL | I43: SALDO FINAL
A46: CAJA INICIAL DEL MES | I46: 58.2
H48: TOTAL | I48: =I42+I46 -> 2584.3

Sheet INGRESOS
D1: INGRESO X COBRO DE RECIBOS DICIEMBRE 2025
D2: DESCRIPCION | F2: MONTO
B3: BARRIO | C3: =COUNTIF(RECIBOS!$D$4:$D$822,INGRESOS!D3) -> 147 | D3: CHAUPI | F3: =SUMIF(RECIBOS!D$4:D$822,"CHAUPI",RECIBOS!L$4:L$822) -> 4397.5
B4: BARRIO | C4: =COUNTIF(RECIBOS!$D$4:$D$822,INGRESOS!D4) -> 132 | D4: PACHAYZA | F4: =SUMIF(RECIBOS!D$4:D$822,"PACHAYZA",RECIBOS!L$4:L$822) -> 3615.5
B5: BARRIO | C5: =COUNTIF(RECIBOS!$D$4:$D$822,INGRESOS!D5) -> 25 | D5: LUCMANI | F5: =SUMIF(RECIBOS!D$4:D$822,"LUCMANI",RECIBOS!L$4:L$822) -> 604
B6: BARRIO | C6: =COUNTIF(RECIBOS!$D$4:$D$822,INGRESOS!D6) -> 11 | D6: HUAQUILLO | F6: =SUMIF(RECIBOS!D$4:D$822,"HUAQUILLO",RECIBOS!L$4:L$822) -> 214
B7: BARRIO | C7: =COUNTIF(RECIBOS!$D$4:$D$822,INGRESOS!D7) -> 1 | D7: AYACUCHO | F7: =SUMIF(RECIBOS!D$4:D$822,"AYACUCHO",RECIBOS!L$4:L$822) -> 6.5
B8: BARRIO | C8: =COUNTIF(RECIBOS!$D$4:$D$822,INGRESOS!D8) -> 4 | D8: CHAUPICERCA | F8: =SUMIF(RECIBOS!D$4:D$822,"CHAUPICERCA",RECIBOS!L$4:L$822) -> 37.5
C9: =SUM(C3:C8) -> 320 | D9: SUMA TOTAL | F9: =SUM(F3:F8) -> 8875
D11: INGRESOS VARIABLES (INSTALACION, CONSTRUCCION Y M.O.) JUNIO2026
B12: FECHA | C12: N° REC. | D12: DESCRIPCION | E12: COD | F12: MONTO
B13: 46174 | C13: 1375 | D13: AMANDA USCAMNAYTA HUAMANI. COMPRA DE TUBO1/2 DE AGUA POTABLE | E13: VA | F13: 23
B14: 46174 | C14: 1376 | D14: EUSEBIA USCAMNAYTA HUAMANI. COMPRA DE TUBO1/2 DE AGUA POTABLE | E14: VA | F14: 23
B15: 46174 | C15: 1377 | D15: HERMOGENES USCAMAYTA VERA.ISTALACION DE AGUA POTABLE | E15: IST | F15: 425
B16: 46174 | C16: 1378 | D16: JANEPP ANASTACIA HUAMANI. PAGO POR CONSTRUCCION DE ENERO A JUNIO | E16: CONS | F16: 600
B17: 46177 | C17: 1379 | D17: EFRAIN BLAS MONTALVO. COMPRA DE UN MEDIDOR | E17: VA | F17: 135 | J17: =SUM(F13+F14+F17+F19+F20+F23+F30+F31) -> 422.5
B18: 46178 | C18: 1380 | D18: NULO | E18: NULO | F18: 0
B19: 46179 | C19: 1381 | D19: GIAN MARTINEZ ZAMBRANO. COMPRA DE UN CODO 1/2. UNIVERSAL 1/2 90° Y UN TEFLON | E19: VA | F19: 8.5 | J19: =SUM(F15+INGRESOS!F16+INGRESOS!F22+INGRESOS!F25+INGRESOS!F26+INGRESOS!F27+INGRESOS!F28+INGRESOS!F29) -> 3629
B20: 46182 | C20: 1382 | D20: MARISOL CASTRO HUAMANI. COMPRA DE MEDIDOR | E20: VA | F20: 135
B21: 46182 | C21: 1383 | D21: JORGE HUAMANI URDAY.PAGO POR RECONEXCION DE AGUA POTABLE | E21: RC | F21: 150 | J21: =SUM(F21+F24) -> 300
B22: 46183 | C22: 1384 | D22: YULI TORRES ARUTAYPE. INSTALACION DE DESAGUE | E22: IST | F22: 533
B23: 46183 | C23: 1385 | D23: FAUSTINA MASEDO. COMPRA DE DESAGUE | E23: VA | F23: 18
B24: 46184 | C24: 1386 | D24: YEDY USCAMAYTA. PAGO POR RECONEXION DE AGUA POTABLE | E24: RC | F24: 150 | J24: =SUM(J17+J19+J21) -> 4351.5
B25: 46185 | C25: 1387 | D25: FAUSTINACHUQUIYANQUI. PAGO POR INSTALACION DE AGUA POTABLE | E25: IST | F25: 425
B26: 46185 | C26: 1388 | D26: FAUSTINA CHUQUIYANQUI. PAGO POR INSTALACION DE DESAGUE | E26: IST | F26: 533
B27: 46186 | C27: 1389 | D27: VALENTIN MONTALVO. PAGO POR INSTALACION DE AGUA POTABLE (SIN EL MEDIDOR) | E27: IST | F27: 290
B28: 46186 | C28: 1390 | D28: FAUSTINA CHUQUIYANQUI. PAGO POR INSTALACION DE AGUA POTABLE (SIN EL MEDIDOR) | E28: IST | F28: 290
B29: 46186 | C29: 1391 | D29: VALENTIN MONTALVO. PAGO POR INSTALACION DE DESAGUE | E29: IST | F29: 533
B30: 46189 | C30: 1392 | D30: JUANA SANCHEZ. COMPRA DE CAJA DE MEDIDOR MAS TAPA | E30: VA | F30: 55
B31: 46198 | C31: 1393 | D31: CECILIA FLORES PAGO POR SERVICIO DE AGUA DESDE ENERO HASTA MAYO | E31: VA | F31: 25
F34: =SUM(F13:F33) -> 4351.5
D37: INGRESOS POR GRIFO DE AGUA (JUNIO 2026)
B38: FECHA | C38: N° REC. | D38: DESCRIPCIÓN | E38: COD | F38: MONTO
A39: LUNES | B39: 46174 | C39: 2089 | D39: SERVICIO DE AGUA POTABLE 4 CUBOS. MINERA ORION | E39: GF | F39: 40
B40: 46174 | C40: 2090 | D40: SERVICIO DE AGUA POTABLE 4 CUBOS. MARTHA | E40: GF | F40: 40
B41: 46174 | C41: 2091 | D41: SERVICIO DE AGUA POTABLE 4 CUBOS. MINERA ORION | E41: GF | F41: 40
B42: 46174 | C42: 2092 | D42: SERVICIO DE AGUA POTABLE 3 CUBOS. AGUSTO | E42: GF | F42: 30 | G42: =SUM(F39:F42) -> 150
A43: MARTES | B43: 46175 | C43: 2093 | D43: SERVICIO DE AGUA POTABLE 4 CUBOS. COMEDOR | E43: GF | F43: 40
B44: 46175 | C44: 2094 | D44: SERVICIO DE AGUA POTABLE 4 CUBOS. ORION | E44: GF | F44: 40
B45: 46175 | C45: 2095 | D45: SERVICIO DE AGUA POTABLE 4 CUBOS. MINERA ORION | E45: GF | F45: 40
...

Sheet EGRESOS
B2: EGRESOS DEL MES DE JUNIO 2026
B3: FECHA | C3: N° REC | D3: DESCRIPCION | E3: COD | F3: MONTO
B4: 46174 | C4: 321 | D4: REY HUAMANI ALVARES. DEVOLUCION DE RECIBO N°533055 Y N°56260 | E4: MO | F4: 37
B5: 46174 | C5: 3605140 | D5: PAGO DE LUZ SEAL POR EL MES DE ABRIL Y MARZO 2026 | E5: SB | F5: 77.4
B6: 46176 | C6: BOL. | D6: ESTACIONES SUR ANDINA. GASOLINA | E6: CT | F6: 50
B7: 46176 | C7: REC | D7: COMUNICADO SOBRE CIERRE DE VIA DESDE GRAS SINTETICO HASTA MOYKEY POR AMPLIACION DE RED DE AGUA POTABLE | E7: RD | F7: 75
B8: 46176 | C8: N/P | D8: 2 GASEOSAS . 1 AGUA | E8: MO | F8: 35
B9: 46176 | C9: REC | D9: COMUNICADO SOBRE CIERRE DE VIA DESDE RADIO CARISMA HACIE ARRIBA POR REPARACION DE AVERIA DE TUBERIA | E9: RD | F9: 15
B10: 46176 | C10: 322 | D10: TAXI CRISTIAN NAVINTA. TRASLADO DE EQUIPOS ALQUILADOS GENERADOR.ROTOMATILLO | E10: TX | F10: 50 | J10: AL | L10: =SUM(F13+F19+F41+F43+F60) -> 589.5
B11: 46176 | C11: 323 | D11: TAXI CRISTIAN NAVINTA. TRASLADO DE PERSONAL ASILLO 25-05-2026 Y RECOJO DE PERSONAL DE SANTA ROSA TURNO NOCHE 01-06-2026 | E11: TX | F11: 200 | J11: CT | L11: =SUM(F6+F25+F38) -> 135
B12: 46176 | C12: 324 | D12: GARY SALAR DONMIGEZ. PAGO DE PERSONAL POR PURGAR AGUA DE ASILLO 25-05-2026 Y 01-06-2026 | E12: SC | F12: 400 | J12: TX | L12: =SUM(F10+F11+F14+F16+F27+F32+F39+F49+F52+F55+F57+F58+F62+F63+F65+F66+F68+F70+F72+F76) -> 1025
B13: 46178 | C13: N/P | D13: 1 AGUA DE 3LT. GASEOSA DE 3LT | E13: AL | F13: 22.5 | J13: RE | L13: =SUM(F35) -> 2000
B14: 46178 | C14: 325 | D14: TAXI ELVIS TORRES. TRASLADO DE HERRAMIENTAS PACHAYZA A OFICCINA CAAPD | E14: TX | F14: 20
B15: 46181 | C15: N/P | D15: ALIMENTACION POR CONSUMO DE TRABAJADORES PARA EL MANTENIMIENTO DEL PTAR | E15: AL | F15: 695
B16: 46181 | C16: 326 | D16: TAXI YORDI LIBAQUE. PARA EL TRASLADO DE MATERIALES OFICINA A PACHAYZA | E16: TX | F16: 15 | J16: LC | L16: =SUM(F21+F28+F29+F34) -> 800
B17: 46181 | C17: 327 | D17: CARLOS CHAUCAYANQUI. PAGO A PERSONAL POR ARREGLO DE TUBERIA EN EL SECTOR DE PACHAYZA | E17: SC | F17: 100 | J17: SC | L17: =SUM(F12+F17+F18+F23+F26+F31+F37+F46+F47+F48+F50+F53+F64+F67+F71+F74+F75) -> 7440
B18: 46181 | C18: 328 | D18: GARY SALAR DONMIGEZ. PAGO DE PERSONAL POR ARREGLODE TUBERIA EN EL SECTOR DE PACHAYZA | E18: SC | F18: 100 | J18: OF | L18: =SUM(F4+F8+F20+F40+F42+F44+F51+F54+F56+F61) -> 644.5
B19: 46181 | C19: BOL. | D19: 2 ALMUERZOS. POR ARREGLO DE TUBERIA | E19: AL | F19: 20 | J19: M | L19: =SUM(F24+F59+F73) -> 1270
B20: 46181 | C20: BOL. | D20: 1 GASEOSA.1PQTE DE GALLETAS.1 ENCENDEDOR | E20: MO | F20: 18.5 | J20: RD | L20: =SUM(F7+F9+F69) -> 180
B21: 46181 | C21: 329 | D21: LECTURADO DEL MES DE MAYO.YOBANA USCAMAYTA 01-06-26 Y 02-06-2026 | E21: LC | F21: 200 | J21: SB | L21: =SUM(F5+F30) -> 207.4
B22: 46182 | C22: 330 | D22: NULO | E22: NULO | F22: 0
B23: 46182 | C23: 331 | D23: GARY MACOY PAGO A PERSONAL (2) POR DESCARGAR MATERIALES Y ACCESORIOS | E23: SC | F23: 160 | L23: =SUM(L10:L21) -> 14291.4
B24: 46182 | C24: REC | D24: PAGO POR HORAS DE MAQUINARIA (4H) RETRO420 | E24: M | F24: 800
B25: 46182 | C25: BOL. | D25: COMPRA DE GASOLINA PARA LA CUATRIMOTO | E25: CT | F25: 50
B26: 46183 | C26: 332 | D26: PAGO A PERSONAL POR ESCARBO DE MEDIDOR (CORTE) | E26: SC | F26: 50
B27: 46183 | C27: 333 | D27: TAXI KENJI LIBAQUE. TRASLADO DE MATERIALES (FIERROS Y ALAMBRES) PARA CONSTRUCCION DE ROMPEPRESION | E27: TX | F27: 40
B28: 46183 | C28: 334 | D28: LECTURADO DEL MES DE MAYO.LUIS TORRES 01-06-26 Y 02-06-2026 | E28: LC | F28: 200
B29: 46183 | C29: 335 | D29: LECTURADO DEL MES DE MAYO.NELSON TORRES 01-06-26 Y 02-06-2026 | E29: LC | F29: 200
B30: 46184 | C30: BOL. | D30: PAGO DEL SERVICIO DE INTERNET MES DE MAYO | E30: SB | F30: 130
B31: 46185 | C31: 336 | D31: CARLOS CHAUCAYANQUI. PAGO A PERSONAL POR PURGAR LA RED MATRIZ DE ASILLO | E31: SC | F31: 50
B32: 46185 | C32: 337 | D32: TAXI JORGE.TRASLADO IDA Y VUELTA DE PERSONAL PARA PURGAR EL AGUA DE LA RED MATRIZ DE ASILLO | E32: TX | F32: 100
B33: 46185 | C33: 338 | D33: NULO | E33: NULO | F33: 0
B34: 46185 | C34: 339 | D34: LECTURADO DEL MES DE MAYO.JAMES TORRES 01-06-26 Y 02-06-2026 | E34: LC | F34: 200
B35: 46185 | C35: 340 | D35: REMUNERACION SECRETRARIA MES DE MAYO | E35: RE | F35: 2000
B36: 46186 | C36: 341 | D36: NULO | E36: NULO | F36: 0
B37: 46186 | C37: 342 | D37: CARLOS CHAUCAYANQUI. PAGO A POR AMPLIACION DE LA RED DE MATRIZ PACHAYZA 25/05/26 AL 05/06/26 11 DIAS | E37: SC | F37: 1320
B38: 46188 | C38: BOL. | D38: GASOLINA PARA CUATRIMOTO | E38: CT | F38: 35
B39: 46188 | C39: N/P | D39: TAXI TRASLADO DE PERSONAL HACIA LUCMANI PARA REVISAR RED MATRIZ | E39: TX | F39: 30
B40: 46189 | C40: N/P | D40: 1 PAQ DE AGUA 600ML | E40: MO | F40: 24
B41: 46189 | C41: N/P | D41: 4 ALMUERZOS. 1 COCA COLA 3L. 1 COCA COLA DE 1LT. POR ARREGLO DE TUBERIA EN PACHAYZA | E41: AL | F41: 60
...

Sheet RESUMEN JUNIO
D1: RESUMEN DE CAJA CHICA MES JUNIO 2026
E4: INGRESOS | G4: MONTO | I4: rellenar
C5: COBRO DE RECIBOS
D6: Chaupi | E6: 147 | F6: 4397.5 | G6: =F5+F6+F7+F8+F9+F10+F11 -> 8875
D7: Pachayza | E7: 132 | F7: 3615.5
D8: Lucmani | E8: 25 | F8: 604
D9: Huaquillo | E9: 11 | F9: 214
D10: Ayacucho | E10: 1 | F10: 6.5
D11: Chaupicerca | E11: 4 | F11: 37.5
D12: USUARIOS | E12: =SUM(E6:E11) -> 320
C13: INGRESO VARIABLE (Instalaciones, x construccion, M. O.) | G13: 3629
C14: MULTAS (reconexion) | G14: 300
C15: VENTAS DE ACCESORIOS Y TUBOS | G15: 422.5
C16: INGRESO GRIFO DE AGUA | G16: 4230
C17: COPIAS E IMPRESIONES, DOCUMENTOS | G17: 56
F18: INGRESO TOTAL | G18: =SUM(G6:G17) -> 17512.5
E20: EGRESOS | G20: MONTO
C21: ALIMENTACION (directiva, personal y otros) | G21: 1284.5
C22: CUATRIMOTO (gasolina ) | G22: 135
C23: MATERIALES Y/O ACCESORIOS (lampara, toma corriente y otros) | G23: 644.5
C24: MOVILIDAD (servicio de taxis) | G24: 1025
C25: MAQUINARIA ( alquiler de retro excabadora, rotomartillo ) | G25: 1270
C26: REMUNERACION (secretaria ) | G26: 2000
C27: LECTURADOS (pago a personal) | G27: 800
C28: SERVICIOS CONTRATADOS ( personal de apoyo,peones, servicio de limpieza, otros) | G28: 7440
C29: SERVICIOS BASICOS ( luz,internet ) | G29: 207.4
C30: COMUNICADOS EN LA RADIO | G30: 180
F32: EGRESO TOTAL | G32: =SUM(G21:G30) -> 14986.4
F34: SALDO | G34: =G18-G32 -> 2526.1

Sheet CORTE
A1: USUARIOS EN CORTE
A3: CONEXIÓN | B3: N° MEDIDOR | C3: BARRIO | D3: BENEFICIARIO | E3: DIRECCIÓN | F3: OBSERVACIONES
A4: 000531 | B4: 6563939 | C4: AYACUCHO | D4: TORRES HUAMANI,AMELIA BENITA | E4: S/N | F4: OCT-NOV-DIC S/21.00 CORTE | H4: CORTE
A5: 000669 | B5: 21003048 | C5: LUCMANI | D5: CHAVEZ ANTACHOQUE HENRRY | E5: SECTOR JENCHO | F5: OCT-NOV-DIC S/78.50 CORTE | H5: CORTE
A6: 000691 | B6: 21000863 | C6: LUCMANI | D6: GUTIERREZ CHALCO REYNALDO ROBERTO | E6: LUCMANI S/N | F6: SET-OCT-NOV-DIC S/20.00 CORTE | H6: CORTE
A7: 000023 | B7: 21000864 | C7: LUCMANI | D7: HUAMANI COA,LUCIO INGNACIO | E7: LUCMANI S/N | F7: OCT-NOV-DIC S/65.50 CORTE | H7: CORTE
A8: 000032 | B8: 6572092 | C8: LUCMANI | D8: LUQUE VERA,ELISA LURDES | E8: LUCMANI S/N | F8: OCT-NOV-DIC S/31.00 CORTE | H8: CORTE
A9: 000047 | B9: 6660664 | C9: LUCMANI | D9: PALOMINO NEYRA,JUSTINA LUZ | E9: LUCMANI S/N | F9: OCT-NOV-DIC S/34.50 CORTE | H9: CORTE
A10: 000049 | B10: 6591593 | C10: LUCMANI | D10: RAMIREZ HUAMANI,MARIA LETICIA | E10: LUCMANI S/N | F10: SET-OCT-NOV-DIC S/20.00 CORTE | H10: CORTE
A11: 000498 | B11: 60062505 | C11: CHAUPI | D11: ALFARO NEYRA DE CHUQUIYANQUI LUCIA POMPEYA | E11: PASAJE SAN ISIDRO S/N | F11: OCT-NOV-DIC S/15.00 CORTE | H11: CORTE
A12: 000278 | B12: 60062464 | C12: CHAUPI | D12: ANTACHOQUE NAVINTA ,LETDY EVANIA | E12: CALLE CUYO CUYO S/N | F12: SET-OCT-NOV-DIC S/20.00 CORTE | H12: CORTE
A13: 000283 | B13: 6562501 | C13: CHAUPI | D13: AYMARA ALFARO ,FROILAN ANDRES | E13: CALLE 28 DE JULIO S/N | F13: OCT-NOV-DIC S/114.50 CORTE | H13: CORTE
A14: 000300 | B14: 60061426 | C14: CHAUPI | D14: CATEDRAL DE LA COMUNIDAD DE ISPACAS | E14: CALLE CUYO CUYO S/N | F14: SET-OCT-NOV-DIC S/ 132.00 CORTE | H14: CORTE
A15: 000301 | B15: 6562439 | C15: CHAUPI | D15: CHALCO ESCOBAR ,CALIXTO EUGENIO | E15: LUCMANI S/N | F15: OCT-NOV-DIC S/15.00 CORTE | H15: CORTE
... A95: 000740 | B95: 23022182 | C95: PACHAYZA | D95: VERA SIVINCHA, ANDRES PEDRO | E95: AHUINTA-PACHAYZA | F95: OCT-NOV-DIC S/65.50 CORTE | H95: CORTE
A97: USUARIOS EN CONSTRUCCIÓN POR USO DE AGUA
A99: CONEXIÓN | B99: N° MEDIDOR | C99: BARRIO | D99: BENEFICIARIO | E99: DIRECCIÓN | F99: OBSERVACIONES
A100: 000043 | B100: 6578514 | C100: LUCMANI | D100: NEIRA DE ROMERO,EDUARDA FERNANDINA | E100: LUCMANI S/N | F100: CONSTRUCCION SET-OCTUBRE
A101: 000694 | B101: 21130885 | C101: CHAUPI | D101: CHAVEZ TORRES CASTOR MILTON | E101: CALLE 5 DE AGOSTO S/N | F101: CONSTRUCCION MES DE ENERO
A102: 000340 | B102: 60061410 | C102: CHAUPI | D102: CRUZ MANCILLA ,NOYA SAIDA | E102: AVENIDA AVIACION S/N | F102: CONSTRUCCION MES DE ENERO
A103: 000605 | B103: 190005360 | C103: CHAUPI | D103: HUAMANI ESCOBAR AYNETH | E103: CALLE 28 DE JULIO | F103: CONSTRUCCION MES DE ENERO
A104: 000363 | B104: 23022175 | C104: CHAUPI | D104: HUAMANI ALVAREZ ,NELIDA LUZ | E104: LUCMANI S/N | F104: COSTRUCCIÓN SETIEMBRE OCTUBRE
A105: 000586 | B105: 09093268 | C105: CHAUPI | D105: ANTACHOQUE ESCOBAR, FANY KELIDA | E105: LUCMANI S/N | F105: CONSTRUCCIÓN MES DE JUNIO - JULIO
A106: 000290 | B106: 6573791 | C106: CHAUPI | D106: LLERENA MONTALVO DE CARPIO MAXIMILIANA | E106: CALLE LOS ESTUDIANTES S/N | F106: CONSTRUCCION MES SOLO ENERO, SOLO JUNIO.
A107: 000705 | B107: 23013263 | C107: CHAUPI | D107: MANCILLA VERA SUSY MARIBEL | E107: CALLE 5 DE AGOSTO S/N | F107: CONSTRUCCION MES DE ENERO
A108: 000508 | B108: 60062489 | C108: CHAUPI | D108: USCAMAYTA HUAMANI ,JESUS | E108: CALLE JUAN USCAMAYTA S/N | F108: CONSTRUCCION MES DE ENERO
A109: 000295 | B109: 6590154 | C109: CHAUPI | D109: CASTRO HUAMANI ,LEONCIO | E109: CHAUPI | F109: CONSTRUCCION
A110: 000558 | B110: 10786 | C110: CHAUPI | D110: HUAMANI HUAMANI,JANETT ANASTACIA | E110: CALLE EL OLVIDO S/N | F110: CONSTRUCCION MES DE OCTUBRE,NOVIEMBRE
... A137: 000259 | B137: 6587730 | C137: PACHAYZA | D137: RAMIREZ USCAMAYTA, JAIME MAURO | E137: SECTOR PACHAYZA -TARAPATA | F137: CONSTRUCCIÓN AGOSTO
A140: USUARIOS CON MEDIDORES ENTERRADOS, SEGUIMIENTO, MALOGRADOS, LIMPIAR MEDIDOR,CAMBIO DE MEDIDOR
A142: CONEXIÓN | B142: N° MEDIDOR | C142: BARRIO | D142: BENEFICIARIO | E142: DIRECCIÓN | F142: OBSERVACIONES | G142: RESP.
A143: 000741 | B143: 22115452 | C143: CHAUPI | D143: CHALCO MONTALVO, GLORIA VICTORIA | E143: CALLE VIRGEN DE LAS NIEVES S/N | F143: ENTERRADO
A144: 000654 | B144: 200005319 | C144: CHAUPI | D144: CHALCO MONTALVO, YOBANA DEBORA | E144: CALLE 5 DE AGOSTO | F144: ENTERRADO
A145: 000770 | B145: 22393000 | C145: CHAUPI | D145: CORTES ZURITA, JUAN FRANSISCO | E145: LUCMANI S/N | F145: ENTERRADO
A146: 000419 | B146: 6558327 | C146: CHAUPI | D146: MONTALVO HUAMANI ,JANO JUAN | E146: CALLE SAN SEBASTIAN S/N | F146: REGISTRO DE DESAGUE MALOGRADO
A147: 000363 | B147: 23022175 | C147: CHAUPI | D147: HUAMANI ALVAREZ ,NELIDA LUZ | E147: LUCMANI S/N | F147: ENTERRADO
A148: 000508 | B148: 60062489 | C148: CHAUPI | D148: USCAMAYTA HUAMANI ,JESUS | E148: CALLE JUAN USCAMAYTA S/N | F148: ENTERRADO
A149: 000729 | B149: 220017506 | C149: CHAUPI | D149: USCAMAYTA MONTALVO, MARITA BERNA | E149: CALLE JUAN USCAMAYTA S/N | F149: ENTERRADO
A150: 000754 | B150: 22393040 | C150: CHAUPI | D150: HUAMANI , LUZ HAYDE | E150: PSJ VIRGEN DE LAS NIEVES | F150: ENTERRADO
A151: 000638 | B151: 200002890 | C151: CHAUPI | D151: TILLCA MENDOZA YANED | E151: CALLE AVIACION S/N | F151: ENTERRADO
...
